---
title: "Gérer les erreurs dans une fonction avec tryCatch"
menu_order: 1
post_status: publish
taxonomy:
    category:
        - gestion d'erreurs
    post_tag:
        - tryCatch
        - erreurs
---

# Gérer les erreurs dans une fonction avec `tryCatch` en R

En programmation, il est courant de rencontrer des erreurs qui peuvent interrompre l'exécution de votre code. En R, la fonction `tryCatch` est un outil puissant qui vous permet de gérer ces erreurs de manière élégante. Cet article vous expliquera comment utiliser `tryCatch` pour capturer et gérer les erreurs dans vos fonctions.

## Qu'est-ce que `tryCatch` ?

`tryCatch` est une fonction qui vous permet d'exécuter du code tout en spécifiant comment gérer les erreurs qui peuvent survenir. Elle prend trois arguments principaux :

1. **expr** : l'expression à évaluer.
2. **error** : une fonction qui sera exécutée si une erreur se produit.
3. **warning** : une fonction qui sera exécutée si un avertissement se produit (facultatif).
4. **finally** : une fonction qui sera exécutée à la fin, qu'il y ait eu une erreur ou non (facultatif).

## Exemple de code

Prenons un exemple simple où nous voulons diviser deux nombres. Nous allons gérer les erreurs potentielles, comme la division par zéro.

```r
# Fonction pour diviser deux nombres
diviser <- function(x, y) {
  result <- tryCatch({
    # Essayer de faire la division
    x / y
  }, error = function(e) {
    # Gérer l'erreur en cas de division par zéro
    message("Erreur : ", e$message)
    return(NA)  # Retourner NA en cas d'erreur
  }, finally = {
    message("Fin de la tentative de division.")
  })
  
  return(result)
}

# Testons la fonction
print(diviser(10, 2))  # Devrait afficher 5
print(diviser(10, 0))  # Devrait afficher un message d'erreur et NA
```

## Explications

Dans cet exemple, nous avons défini une fonction `diviser` qui prend deux arguments, `x` et `y`. À l'intérieur de la fonction, nous utilisons `tryCatch` pour tenter de diviser `x` par `y`.

- Si la division réussit, le résultat est retourné.
- Si une erreur se produit (par exemple, si `y` est égal à zéro), la fonction d'erreur est appelée, affichant un message d'erreur et retournant `NA`.
- Le bloc `finally` est exécuté à la fin, qu'il y ait eu une erreur ou non, ce qui nous permet d'afficher un message indiquant que la tentative de division est terminée.

## Conclusion

Utiliser `tryCatch` en R est une excellente manière de rendre votre code plus robuste et de gérer les erreurs de manière proactive. Cela vous permet d'éviter des interruptions inattendues et de fournir des messages d'erreur clairs à l'utilisateur. N'hésitez pas à intégrer `tryCatch` dans vos propres fonctions pour améliorer la gestion des erreurs dans vos projets R !

